Workbook

Sheet Sales_Data
A1: Order_ID | B1: Date | C1: Salesperson | D1: Region | E1: Category | F1: Product | G1: Quantity | H1: Unit_Price | I1: Discount_% | J1: Revenue | K1: Cost | L1: Profit
A2: 1 | B2: 2024-01-08 | C2: Bob | D2: North | E2: Electronics | F2: Laptop | G2: 9 | H2: 1200 | I2: 5 | J2: =G2*H2*(1-I2/100) -> 10260 | K2: =G2*720 -> 6480 | L2: =J2-K2 -> 3780
A3: 2 | B3: 2024-01-19 | C3: David | D3: North | E3: Food | F3: Cookies | G3: 18 | H3: 8 | I3: 0 | J3: =G3*H3*(1-I3/100) -> 144 | K3: =G3*4.8 -> 86.4 | L3: =J3-K3 -> 57.6
A4: 3 | B4: 2024-01-17 | C4: Eva | D4: North | E4: Electronics | F4: Laptop | G4: 7 | H4: 1200 | I4: 5 | J4: =G4*H4*(1-I4/100) -> 7980 | K4: =G4*720 -> 5040 | L4: =J4-K4 -> 2940
A5: 4 | B5: 2024-01-08 | C5: David | D5: East | E5: Food | F5: Coffee | G5: 18 | H5: 15 | I5: 15 | J5: =G5*H5*(1-I5/100) -> 229.5 | K5: =G5*9 -> 162 | L5: =J5-K5 -> 67.5
A6: 5 | B6: 2024-01-09 | C6: Bob | D6: South | E6: Electronics | F6: Laptop | G6: 14 | H6: 1200 | I6: 10 | J6: =G6*H6*(1-I6/100) -> 15120 | K6: =G6*720 -> 10080 | L6: =J6-K6 -> 5040
A7: 6 | B7: 2024-01-04 | C7: Carol | D7: East | E7: Clothing | F7: T-Shirt | G7: 3 | H7: 25 | I7: 15 | J7: =G7*H7*(1-I7/100) -> 63.75 | K7: =G7*15 -> 45 | L7: =J7-K7 -> 18.75
A8: 7 | B8: 2024-01-18 | C8: Alice | D8: West | E8: Food | F8: Tea | G8: 2 | H8: 10 | I8: 15 | J8: =G8*H8*(1-I8/100) -> 17 | K8: =G8*6 -> 12 | L8: =J8-K8 -> 5
A9: 8 | B9: 2024-01-28 | C9: Carol | D9: South | E9: Electronics | F9: Tablet | G9: 10 | H9: 400 | I9: 20 | J9: =G9*H9*(1-I9/100) -> 3200 | K9: =G9*240 -> 2400 | L9: =J9-K9 -> 800
A10: 9 | B10: 2024-01-25 | C10: Carol | D10: North | E10: Food | F10: Coffee | G10: 2 | H10: 15 | I10: 5 | J10: =G10*H10*(1-I10/100) -> 28.5 | K10: =G10*9 -> 18 | L10: =J10-K10 -> 10.5
A11: 10 | B11: 2024-01-15 | C11: Carol | D11: South | E11: Electronics | F11: Laptop | G11: 13 | H11: 1200 | I11: 10 | J11: =G11*H11*(1-I11/100) -> 14040 | K11: =G11*720 -> 9360 | L11: =J11-K11 -> 4680
A12: 11 | B12: 2024-01-23 | C12: Alice | D12: South | E12: Clothing | F12: Jeans | G12: 7 | H12: 60 | I12: 10 | J12: =G12*H12*(1-I12/100) -> 378 | K12: =G12*36 -> 252 | L12: =J12-K12 -> 126
A13: 12 | B13: 2024-01-15 | C13: David | D13: East | E13: Food | F13: Cookies | G13: 8 | H13: 8 | I13: 5 | J13: =G13*H13*(1-I13/100) -> 60.8 | K13: =G13*4.8 -> 38.4 | L13: =J13-K13 -> 22.4
A14: 13 | B14: 2024-01-22 | C14: Carol | D14: North | E14: Food | F14: Cookies | G14: 18 | H14: 8 | I14: 5 | J14: =G14*H14*(1-I14/100) -> 136.8 | K14: =G14*4.8 -> 86.4 | L14: =J14-K14 -> 50.4
A15: 14 | B15: 2024-01-09 | C15: Alice | D15: South | E15: Electronics | F15: Laptop | G15: 11 | H15: 1200 | I15: 15 | J15: =G15*H15*(1-I15/100) -> 11220 | K15: =G15*720 -> 7920 | L15: =J15-K15 -> 3300
A16: 15 | B16: 2024-01-21 | C16: David | D16: West | E16: Food | F16: Cookies | G16: 11 | H16: 8 | I16: 5 | J16: =G16*H16*(1-I16/100) -> 83.6 | K16: =G16*4.8 -> 52.8 | L16: =J16-K16 -> 30.8
A17: 16 | B17: 2024-01-05 | C17: Bob | D17: East | E17: Food | F17: Tea | G17: 5 | H17: 10 | I17: 10 | J17: =G17*H17*(1-I17/100) -> 45 | K17: =G17*6 -> 30 | L17: =J17-K17 -> 15
A18: 17 | B18: 2024-01-13 | C18: Carol | D18: South | E18: Food | F18: Cookies | G18: 14 | H18: 8 | I18: 20 | J18: =G18*H18*(1-I18/100) -> 89.6 | K18: =G18*4.8 -> 67.2 | L18: =J18-K18 -> 22.4
A19: 18 | B19: 2024-01-25 | C19: Alice | D19: North | E19: Electronics | F19: Tablet | G19: 16 | H19: 400 | I19: 0 | J19: =G19*H19*(1-I19/100) -> 6400 | K19: =G19*240 -> 3840 | L19: =J19-K19 -> 2560
A20: 19 | B20: 2024-01-20 | C20: Alice | D20: West | E20: Electronics | F20: Tablet | G20: 6 | H20: 400 | I20: 15 | J20: =G20*H20*(1-I20/100) -> 2040 | K20: =G20*240 -> 1440 | L20: =J20-K20 -> 600
A21: 20 | B21: 2024-01-09 | C21: Eva | D21: North | E21: Clothing | F21: Jacket | G21: 15 | H21: 120 | I21: 20 | J21: =G21*H21*(1-I21/100) -> 1440 | K21: =G21*72 -> 1080 | L21: =J21-K21 -> 360
A22: 21 | B22: 2024-01-25 | C22: Carol | D22: East | E22: Food | F22: Cookies | G22: 4 | H22: 8 | I22: 20 | J22: =G22*H22*(1-I22/100) -> 25.6 | K22: =G22*4.8 -> 19.2 | L22: =J22-K22 -> 6.4
A23: 22 | B23: 2024-01-15 | C23: Alice | D23: East | E23: Electronics | F23: Phone | G23: 14 | H23: 600 | I23: 5 | J23: =G23*H23*(1-I23/100) -> 7980 | K23: =G23*360 -> 5040 | L23: =J23-K23 -> 2940
A24: 23 | B24: 2024-01-28 | C24: Carol | D24: South | E24: Food | F24: Coffee | G24: 17 | H24: 15 | I24: 0 | J24: =G24*H24*(1-I24/100) -> 255 | K24: =G24*9 -> 153 | L24: =J24-K24 -> 102
A25: 24 | B25: 2024-01-25 | C25: Eva | D25: North | E25: Electronics | F25: Phone | G25: 6 | H25: 600 | I25: 20 | J25: =G25*H25*(1-I25/100) -> 2880 | K25: =G25*360 -> 2160 | L25: =J25-K25 -> 720
A26: 25 | B26: 2024-01-04 | C26: Carol | D26: East | E26: Food | F26: Tea | G26: 16 | H26: 10 | I26: 0 | J26: =G26*H26*(1-I26/100) -> 160 | K26: =G26*6 -> 96 | L26: =J26-K26 -> 64
A27: 26 | B27: 2024-02-03 | C27: David | D27: North | E27: Electronics | F27: Laptop | G27: 19 | H27: 1200 | I27: 0 | J27: =G27*H27*(1-I27/100) -> 22800 | K27: =G27*720 -> 13680 | L27: =J27-K27 -> 9120
A28: 27 | B28: 2024-02-18 | C28: Bob | D28: East | E28: Food | F28: Coffee | G28: 5 | H28: 15 | I28: 15 | J28: =G28*H28*(1-I28/100) -> 63.75 | K28: =G28*9 -> 45 | L28: =J28-K28 -> 18.75
A29: 28 | B29: 2024-02-18 | C29: Bob | D29: East | E29: Food | F29: Cookies | G29: 14 | H29: 8 | I29: 5 | J29: =G29*H29*(1-I29/100) -> 106.4 | K29: =G29*4.8 -> 67.2 | L29: =J29-K29 -> 39.2
A30: 29 | B30: 2024-02-17 | C30: David | D30: North | E30: Clothing | F30: Jacket | G30: 12 | H30: 120 | I30: 15 | J30: =G30*H30*(1-I30/100) -> 1224 | K30: =G30*72 -> 864 | L30: =J30-K30 -> 360
A31: 30 | B31: 2024-02-01 | C31: Eva | D31: South | E31: Electronics | F31: Laptop | G31: 3 | H31: 1200 | I31: 10 | J31: =G31*H31*(1-I31/100) -> 3240 | K31: =G31*720 -> 2160 | L31: =J31-K31 -> 1080
A32: 31 | B32: 2024-02-23 | C32: Alice | D32: South | E32: Food | F32: Coffee | G32: 1 | H32: 15 | I32: 0 | J32: =G32*H32*(1-I32/100) -> 15 | K32: =G32*9 -> 9 | L32: =J32-K32 -> 6
A33: 32 | B33: 2024-02-17 | C33: Bob | D33: East | E33: Electronics | F33: Laptop | G33: 11 | H33: 1200 | I33: 0 | J33: =G33*H33*(1-I33/100) -> 13200 | K33: =G33*720 -> 7920 | L33: =J33-K33 -> 5280
A34: 33 | B34: 2024-02-05 | C34: Eva | D34: West | E34: Food | F34: Tea | G34: 7 | H34: 10 | I34: 20 | J34: =G34*H34*(1-I34/100) -> 56 | K34: =G34*6 -> 42 | L34: =J34-K34 -> 14
A35: 34 | B35: 2024-02-04 | C35: Alice | D35: West | E35: Electronics | F35: Phone | G35: 14 | H35: 600 | I35: 5 | J35: =G35*H35*(1-I35/100) -> 7980 | K35: =G35*360 -> 5040 | L35: =J35-K35 -> 2940
A36: 35 | B36: 2024-02-28 | C36: Alice | D36: North | E36: Clothing | F36: Jeans | G36: 14 | H36: 60 | I36: 15 | J36: =G36*H36*(1-I36/100) -> 714 | K36: =G36*36 -> 504 | L36: =J36-K36 -> 210
A37: 36 | B37: 2024-02-08 | C37: Bob | D37: South | E37: Electronics | F37: Phone | G37: 11 | H37: 600 | I37: 0 | J37: =G37*H37*(1-I37/100) -> 6600 | K37: =G37*360 -> 3960 | L37: =J37-K37 -> 2640
A38: 37 | B38: 2024-02-06 | C38: Carol | D38: West | E38: Food | F38: Tea | G38: 5 | H38: 10 | I38: 15 | J38: =G38*H38*(1-I38/100) -> 42.5 | K38: =G38*6 -> 30 | L38: =J38-K38 -> 12.5
A39: 38 | B39: 2024-02-04 | C39: Alice | D39: North | E39: Electronics | F39: Laptop | G39: 15 | H39: 1200 | I39: 20 | J39: =G39*H39*(1-I39/100) -> 14400 | K39: =G39*720 -> 10800 | L39: =J39-K39 -> 3600
A40: 39 | B40: 2024-02-16 | C40: David | D40: South | E40: Electronics | F40: Laptop | G40: 6 | H40: 1200 | I40: 15 | J40: =G40*H40*(1-I40/100) -> 6120 | K40: =G40*720 -> 4320 | L40: =J40-K40 -> 1800
...

Sheet Summary
A1: OVERALL KPIs | D1: Revenue by Category | I1: Revenue by Salesperson
D2: Category | E2: Revenue | F2: Profit | G2: % of Total | I2: Salesperson | J2: Revenue | K2: Orders | L2: Avg/Order | M2: Rank
A3: Total Orders | B3: =COUNTA(Sales_Data!A2:A230) -> 229 | D3: Electronics | E3: =SUMIF(Sales_Data!E2:E230,D3,Sales_Data!J2:J230) -> 594990 | F3: =SUMIF(Sales_Data!E2:E230,D3,Sales_Data!L2:L230) -> 201870 | G3: =E3/$B$4 -> 0.90615765 | I3: Alice | J3: =SUMIF(Sales_Data!C2:C230,I3,Sales_Data!J2:J230) -> 157613.8 | K3: =COUNTIF(Sales_Data!C2:C230,I3) -> 45 | L3: =J3/K3 -> 3502.5289 | M3: =RANK(J3,J3:J7,0) -> 2
A4: Total Revenue | B4: =SUM(Sales_Data!J2:J230) -> 656607.6 | D4: Clothing | E4: =SUMIF(Sales_Data!E2:E230,D4,Sales_Data!J2:J230) -> 53895.5 | F4: =SUMIF(Sales_Data!E2:E230,D4,Sales_Data!L2:L230) -> 17385.5 | G4: =E4/$B$4 -> 0.082081749 | I4: Bob | J4: =SUMIF(Sales_Data!C2:C230,I4,Sales_Data!J2:J230) -> 219516.2 | K4: =COUNTIF(Sales_Data!C2:C230,I4) -> 46 | L4: =J4/K4 -> 4772.0913 | M4: =RANK(J4,J3:J7,0) -> 1
A5: Total Cost | B5: =SUM(Sales_Data!K2:K230) -> 434722.8 | D5: Food | E5: =SUMIF(Sales_Data!E2:E230,D5,Sales_Data!J2:J230) -> 7722.1 | F5: =SUMIF(Sales_Data!E2:E230,D5,Sales_Data!L2:L230) -> 2629.3 | G5: =E5/$B$4 -> 0.011760601 | I5: Carol | J5: =SUMIF(Sales_Data!C2:C230,I5,Sales_Data!J2:J230) -> 111148.75 | K5: =COUNTIF(Sales_Data!C2:C230,I5) -> 48 | L5: =J5/K5 -> 2315.599 | M5: =RANK(J5,J3:J7,0) -> 3
A6: Total Profit | B6: =SUM(Sales_Data!L2:L230) -> 221884.8 | I6: David | J6: =SUMIF(Sales_Data!C2:C230,I6,Sales_Data!J2:J230) -> 97822.65 | K6: =COUNTIF(Sales_Data!C2:C230,I6) -> 53 | L6: =J6/K6 -> 1845.7104 | M6: =RANK(J6,J3:J7,0) -> 4
A7: Avg Order Value | B7: =B4/B3 -> 2867.2821 | I7: Eva | J7: =SUMIF(Sales_Data!C2:C230,I7,Sales_Data!J2:J230) -> 70506.2 | K7: =COUNTIF(Sales_Data!C2:C230,I7) -> 37 | L7: =J7/K7 -> 1905.573 | M7: =RANK(J7,J3:J7,0) -> 5
A8: Avg Discount % | B8: =AVERAGEIF(Sales_Data!I2:I230,">0",Sales_Data!I2:I230) -> 12.445055
A9: Profit Margin % | B9: =B6/B4 -> 0.33792603
A12: Monthly Revenue Trend
A13: Month | B13: Revenue | C13: Profit | D13: MoM Growth %
A14: 2024-01 | B14: =SUMPRODUCT((TEXT(Sales_Data!B2:B230,"yyyy-mm")=A14)*Sales_Data!J2:J230) -> 84277.15 | C14: =SUMPRODUCT((TEXT(Sales_Data!B2:B230,"yyyy-mm")=A14)*Sales_Data!L2:L230) -> 28318.75 | D14: -
A15: 2024-02 | B15: =SUMPRODUCT((TEXT(Sales_Data!B2:B230,"yyyy-mm")=A15)*Sales_Data!J2:J230) -> 81581.15 | C15: =SUMPRODUCT((TEXT(Sales_Data!B2:B230,"yyyy-mm")=A15)*Sales_Data!L2:L230) -> 29013.95 | D15: =(B15-B14)/B14 -> -0.031989691
A16: 2024-03 | B16: =SUMPRODUCT((TEXT(Sales_Data!B2:B230,"yyyy-mm")=A16)*Sales_Data!J2:J230) -> 31298.5 | C16: =SUMPRODUCT((TEXT(Sales_Data!B2:B230,"yyyy-mm")=A16)*Sales_Data!L2:L230) -> 11015.5 | D16: =(B16-B15)/B15 -> -0.61635133
A17: 2024-04 | B17: =SUMPRODUCT((TEXT(Sales_Data!B2:B230,"yyyy-mm")=A17)*Sales_Data!J2:J230) -> 36888 | C17: =SUMPRODUCT((TEXT(Sales_Data!B2:B230,"yyyy-mm")=A17)*Sales_Data!L2:L230) -> 13870.2 | D17: =(B17-B16)/B16 -> 0.17858683
A18: 2024-05 | B18: =SUMPRODUCT((TEXT(Sales_Data!B2:B230,"yyyy-mm")=A18)*Sales_Data!J2:J230) -> 73660.2 | C18: =SUMPRODUCT((TEXT(Sales_Data!B2:B230,"yyyy-mm")=A18)*Sales_Data!L2:L230) -> 22306.8 | D18: =(B18-B17)/B17 -> 0.99686077
A19: 2024-06 | B19: =SUMPRODUCT((TEXT(Sales_Data!B2:B230,"yyyy-mm")=A19)*Sales_Data!J2:J230) -> 54268.65 | C19: =SUMPRODUCT((TEXT(Sales_Data!B2:B230,"yyyy-mm")=A19)*Sales_Data!L2:L230) -> 20541.45 | D19: =(B19-B18)/B18 -> -0.26325682
A20: 2024-07 | B20: =SUMPRODUCT((TEXT(Sales_Data!B2:B230,"yyyy-mm")=A20)*Sales_Data!J2:J230) -> 50175.1 | C20: =SUMPRODUCT((TEXT(Sales_Data!B2:B230,"yyyy-mm")=A20)*Sales_Data!L2:L230) -> 17213.5 | D20: =(B20-B19)/B19 -> -0.075431211
A21: 2024-08 | B21: =SUMPRODUCT((TEXT(Sales_Data!B2:B230,"yyyy-mm")=A21)*Sales_Data!J2:J230) -> 25859.1 | C21: =SUMPRODUCT((TEXT(Sales_Data!B2:B230,"yyyy-mm")=A21)*Sales_Data!L2:L230) -> 7814.7 | D21: =(B21-B20)/B20 -> -0.48462285
A22: 2024-09 | B22: =SUMPRODUCT((TEXT(Sales_Data!B2:B230,"yyyy-mm")=A22)*Sales_Data!J2:J230) -> 17162.75 | C22: =SUMPRODUCT((TEXT(Sales_Data!B2:B230,"yyyy-mm")=A22)*Sales_Data!L2:L230) -> 5577.35 | D22: =(B22-B21)/B21 -> -0.33629747
A23: 2024-10 | B23: =SUMPRODUCT((TEXT(Sales_Data!B2:B230,"yyyy-mm")=A23)*Sales_Data!J2:J230) -> 63523.35 | C23: =SUMPRODUCT((TEXT(Sales_Data!B2:B230,"yyyy-mm")=A23)*Sales_Data!L2:L230) -> 18847.95 | D23: =(B23-B22)/B22 -> 2.7012338
A24: 2024-11 | B24: =SUMPRODUCT((TEXT(Sales_Data!B2:B230,"yyyy-mm")=A24)*Sales_Data!J2:J230) -> 30298.25 | C24: =SUMPRODUCT((TEXT(Sales_Data!B2:B230,"yyyy-mm")=A24)*Sales_Data!L2:L230) -> 10960.25 | D24: =(B24-B23)/B23 -> -0.52303759
A25: 2024-12 | B25: =SUMPRODUCT((TEXT(Sales_Data!B2:B230,"yyyy-mm")=A25)*Sales_Data!J2:J230) -> 107615.4 | C25: =SUMPRODUCT((TEXT(Sales_Data!B2:B230,"yyyy-mm")=A25)*Sales_Data!L2:L230) -> 36404.4 | D25: =(B25-B24)/B24 -> 2.5518685

Sheet Region_Category
A1: Revenue by Region × Category
A2: Region / Category | B2: Electronics | C2: Clothing | D2: Food | E2: Total
A3: North | B3: =SUMPRODUCT((Sales_Data!D2:D230=A3)*(Sales_Data!E2:E230="Electronics")*Sales_Data!J2:J230) -> 195690 | C3: =SUMPRODUCT((Sales_Data!D2:D230=A3)*(Sales_Data!E2:E230="Clothing")*Sales_Data!J2:J230) -> 20598 | D3: =SUMPRODUCT((Sales_Data!D2:D230=A3)*(Sales_Data!E2:E230="Food")*Sales_Data!J2:J230) -> 1704.8 | E3: =SUM(B3:D3) -> 217992.8
A4: South | B4: =SUMPRODUCT((Sales_Data!D2:D230=A4)*(Sales_Data!E2:E230="Electronics")*Sales_Data!J2:J230) -> 141740 | C4: =SUMPRODUCT((Sales_Data!D2:D230=A4)*(Sales_Data!E2:E230="Clothing")*Sales_Data!J2:J230) -> 9855.25 | D4: =SUMPRODUCT((Sales_Data!D2:D230=A4)*(Sales_Data!E2:E230="Food")*Sales_Data!J2:J230) -> 1806.85 | E4: =SUM(B4:D4) -> 153402.1
A5: East | B5: =SUMPRODUCT((Sales_Data!D2:D230=A5)*(Sales_Data!E2:E230="Electronics")*Sales_Data!J2:J230) -> 122610 | C5: =SUMPRODUCT((Sales_Data!D2:D230=A5)*(Sales_Data!E2:E230="Clothing")*Sales_Data!J2:J230) -> 9706 | D5: =SUMPRODUCT((Sales_Data!D2:D230=A5)*(Sales_Data!E2:E230="Food")*Sales_Data!J2:J230) -> 2876 | E5: =SUM(B5:D5) -> 135192
A6: West | B6: =SUMPRODUCT((Sales_Data!D2:D230=A6)*(Sales_Data!E2:E230="Electronics")*Sales_Data!J2:J230) -> 134950 | C6: =SUMPRODUCT((Sales_Data!D2:D230=A6)*(Sales_Data!E2:E230="Clothing")*Sales_Data!J2:J230) -> 13736.25 | D6: =SUMPRODUCT((Sales_Data!D2:D230=A6)*(Sales_Data!E2:E230="Food")*Sales_Data!J2:J230) -> 1334.45 | E6: =SUM(B6:D6) -> 150020.7
A7: Grand Total | B7: =SUM(B3:B6) -> 594990 | C7: =SUM(C3:C6) -> 53895.5 | D7: =SUM(D3:D6) -> 7722.1 | E7: =SUM(E3:E6) -> 656607.6
